Workbook
Name Price_Q1: Analysis!$C$4
Name Price_Q3: Analysis!$C$5
Name Slicer_Discount_Category: #N/A
Name Slicer_Price_Category: #N/A
Name Slicer_Rating_Category: #N/A

Sheet RAW_Data
A1: Product | B1: Current price | C1: old price | D1: Discount | E1: Review | F1: Ratingd
A2: 115 Piece Set Of Multifunctional Precision Screwdrivers | B2: KSh 950 | C2: KSh 1,525 | D2: 0.38 | E2: -2 | F2: 4.5 out of 5
A3: Metal Decorative Hooks Key Hangers Entryway Wall Hooks Towel Hooks - Home | B3: KSh 527 | C3: KSh 999 | D3: 0.47 | E3: -14 | F3: 4.1 out of 5
A4: Portable Mini Cordless Car Vacuum Cleaner - Blue | B4: KSh 2,199 | C4: KSh 2,923 | D4: 0.25 | E4: -24 | F4: 4.6 out of 5
A5: Weighing Scale Digital Bathroom Body Fat Scale USB-Black | B5: KSh 1,580 | C5: KSh 2,499 | D5: 0.37 | E5: -7 | F5: 4.7 out of 5
A6: Portable Home Small Air Humidifier 3-Speed Fan - Green | B6: KSh 1,740 | C6: KSh 2,356 | D6: 0.26 | E6: -5 | F6: 4.8 out of 5
A7: 220V 60W Electric Soldering Iron Kits With Tools, Tips, And Multimeter | B7: KSh 2,999 | C7: KSh 3,290 | D7: 0.09 | E7: -15 | F7: 4 out of 5
A8: 137 Pieces Cake Decorating Tool Set Baking Supplies | B8: KSh 2,319 | C8: KSh 3,032 | D8: 0.24 | E8: -55 | F8: 4.6 out of 5
A9: Desk Foldable Fan Adjustable Fan Strong Wind 3 Gear Usb | B9: KSh 988 | C9: KSh 1,580 | D9: 0.37 | E9: -2 | F9: 4 out of 5
A10: LASA FOLDING TABLE SERVING STAND | B10: KSh 1,274 | C10: KSh 2,800 | D10: 0.55 | E10: -5 | F10: 4.8 out of 5
A11: 13 In 1 Home Repair Tools Box Kit Set | B11: KSh 1,600 | C11: KSh 2,929 | D11: 0.45 | E11: -5 | F11: 3.8 out of 5
A12: Genebre 115 In 1 Screwdriver Repairing Tool Set For IPhone Cellphone Hand Tool | B12: KSh 799 | C12: KSh 999 | D12: 0.2 | E12: -12 | F12: 4.1 out of 5
A13: 100 Pcs Crochet Hook Tool Set Knitting Hook Set With Box | B13: KSh 990 | C13: KSh 1,500 | D13: 0.34 | E13: -39 | F13: 4.7 out of 5
... A22: 3PCS Single Head Knitting Crochet Sweater Needle Set | B22: KSh 38 | C22: KSh 80 | D22: 0.53 | E22: -13 | F22: 3.3 out of 5
A23: 4pcs Bathroom/Kitchen Towel Rack,Roll Paper Holder,Towel Bars,Hook | B23: KSh 1,860 | C23: KSh 3,220 | D23: 0.42
A24: LED Romantic Spaceship Starry Sky Projector,Children's Bedroom Night Light-Blue | B24: KSh 880 | C24: KSh 1,350 | D24: 0.35 | E24: -6 | F24: 4 out of 5
A25: Foldable Overbed Table/Desk | B25: KSh 1,650 | C25: KSh 2,150 | D25: 0.23 | E25: -14 | F25: 4.4 out of 5
A26: LASA 3 Tier Bamboo Shoe Bench Storage Shelf | B26: KSh 2,048 | C26: KSh 4,500 | D26: 0.54 | E26: -7 | F26: 4.3 out of 5
A27: Electronic Digital Display Vernier Caliper | B27: KSh 420 | C27: KSh 647 | D27: 0.35 | E27: -49 | F27: 4.6 out of 5
A28: Portable Wardrobe Nonwoven With 3 Hanging Rods And 6 Storage Shelves | B28: KSh 2,880 | C28: KSh 3,520 | D28: 0.18 | E28: -12 | F28: 3.8 out of 5
A29: 12 Litre Black Insulated Lunch Box | B29: KSh 1,350 | C29: KSh 1,990 | D29: 0.32 | E29: -13 | F29: 3.8 out of 5
A30: 52 Pieces Cake Decorating Tool Set Gift Kit Baking Supplies | B30: KSh 1,758 | C30: KSh 2,499 | D30: 0.3 | E30: -20 | F30: 4.1 out of 5
A31: MultiFunctional Storage Rack Multi-layer Bookshelf | B31: KSh 2,200 | C31: KSh 4,080 | D31: 0.46
A32: Exfoliate And Exfoliate Face Towel - Black | B32: KSh 185 | C32: KSh 382 | D32: 0.52 | E32: -9 | F32: 4.3 out of 5
A33: 12 Litre Insulated Lunch Box Grey | B33: KSh 980 | C33: KSh 1,490 | D33: 0.34 | E33: -12 | F33: 4.7 out of 5
A34: LED Eye Protection Desk Lamp , Study, Reading, USB Fan - Double Pen Holder | B34: KSh 1,820 | C34: KSh 3,490 | D34: 0.48 | E34: -9 | F34: 4.3 out of 5
A35: 53Pcs/Set Yarn Knitting Crochet Hooks With Bag - Fortune Cat | B35: KSh 1,940 | C35: KSh 2,650 | D35: 0.27 | E35: -20 | F35: 4.7 out of 5
A36: 53 Pieces/Set Yarn Knitting Crochet Hooks With Bag - Pansies | B36: KSh 1,980 | C36: KSh 2,699 | D36: 0.27 | E36: -32 | F36: 4.5 out of 5
A37: DIY File Folder, Office Drawer File Holder, Pen Holder, Desktop Storage Rack | B37: KSh 1,620 | C37: KSh 2,690 | D37: 0.4 | E37: -1 | F37: 5 out of 5
A38: Classic Black Cat Cotton Hemp Pillow Case For Home Car | B38: KSh 171 | C38: KSh 360 | D38: 0.53 | E38: -2 | F38: 5 out of 5
A39: Punch-free Great Load Bearing Bathroom Storage Rack Wall Shelf-White | B39: KSh 389 | C39: KSh 656 | D39: 0.41 | E39: -36 | F39: 4.3 out of 5
A40: 1/2/3 Seater Elastic Sofa Cover,Living Room/Home Decor Chair Cover-Grey | B40: KSh 1,620 - KSh 1,980 | C40: KSh 2,200 - KSh 3,200 | D40: 0.38 | E40: -2 | F40: 4.5 out of 5
A41: LASA Stainless Steel Double Wall Mount Soap Dispenser - 500ml | B41: KSh 2,750 | C41: KSh 4,471 | D41: 0.38
A42: 4M Float Switch Water Level Controller -Water Tank | B42: KSh 475 | C42: KSh 931 | D42: 0.49
A43: Modern Sofa Throw Pillow Cover-45x45cm-Blue&Red | B43: KSh 238 | C43: KSh 476 | D43: 0.5
A44: Balloon Insert, Birthday Party Balloon Set, PU Leather | B44: KSh 610 | C44: KSh 1,060 | D44: 0.42
A45: Balloon Insert, Birthday Party Balloon Set, PU Leather | B45: KSh 610 | C45: KSh 1,060 | D45: 0.42
A46: Shower Cap Wide Elastic Band Cover Reusable Bashroom Cap | B46: KSh 2,132 | C46: KSh 2,169 | D46: 0.02
A47: Christmas Elk Fence Yard Lawn Decorations Cute For Holidays | B47: KSh 999 | C47: KSh 2,000 | D47: 0.5
A48: 60W Hot Melt Glue Sprayer - Efficient And Stable Glue Dispensing | B48: KSh 1,190 | C48: KSh 1,785 | D48: 0.33
...

Sheet data_quality_audit
C3: Source Row Count = 115 | G3: Discounts outside 0%-100% = | M3: duplicate count and the fields used to identify duplicates;
C4: Source Column Count = 6 | G4: Negative review counts = 57 | I4: Review entries contain negative signs (e.g., -2.0), resulting from web-scraping artifacts.
G5: Current price greater than Old prices =
C6: Source Blank Count by Column | G6: Ratings Outside 0-5 =
C7: Product | D7: 0
C8: Current Price | D8: 0 | G8: Duplicate Counts
C9: Old Price | D9: 0 | G9: Product | H9: 6
C10: Discount | D10: 0 | G10: Current Price | H10: 12
C11: Review | D11: 58 | G11: Old Price | H11: 22
C12: Ratingd | D12: 58 | G12: Discount | H12: 69
C13: formula used = COUNT(range) | G13: Review | H13: 91
G14: Ratingd | H14: 92
C15: Non Numeric Values
C16: Prices | G16: Price Ranges
C17: Reviews | G17: Current Price | H17: KSh 1,620 - KSh 1,980 | K17: Product row 39 contains price ranges (KSh 1,620 - KSh 1,980 and KSh 2,200 - KSh 3,200).
C18: Discounts | G18: Old Price | H18: KSh 2,200 - KSh 3,200
C19: Ratings
C21: Duplicates: 3 full duplicate rows identified

Sheet Cleaned_Data
A1: Product | B1: Current Price | C1: Old Price | D1: Discount | E1: Review | F1: Rating
A2: 115 Piece Set Of Multifunctional Precision Screwdrivers | B2: 950 | C2: 1525 | D2: 0.38 | E2: 2 | F2: 4.5
A3: Metal Decorative Hooks Key Hangers Entryway Wall Hooks Towel Hooks - Home | B3: 527 | C3: 999 | D3: 0.47 | E3: 14 | F3: 4.1
A4: Portable Mini Cordless Car Vacuum Cleaner - Blue | B4: 2199 | C4: 2923 | D4: 0.25 | E4: 24 | F4: 4.6
A5: Weighing Scale Digital Bathroom Body Fat Scale USB-Black | B5: 1580 | C5: 2499 | D5: 0.37 | E5: 7 | F5: 4.7
A6: Portable Home Small Air Humidifier 3-Speed Fan - Green | B6: 1740 | C6: 2356 | D6: 0.26 | E6: 5 | F6: 4.8
A7: 220V 60W Electric Soldering Iron Kits With Tools, Tips, And Multimeter | B7: 2999 | C7: 3290 | D7: 0.09 | E7: 15 | F7: 4
A8: 137 Pieces Cake Decorating Tool Set Baking Supplies | B8: 2319 | C8: 3032 | D8: 0.24 | E8: 55 | F8: 4.6
A9: Desk Foldable Fan Adjustable Fan Strong Wind 3 Gear Usb | B9: 988 | C9: 1580 | D9: 0.37 | E9: 2 | F9: 4
A10: LASA FOLDING TABLE SERVING STAND | B10: 1274 | C10: 2800 | D10: 0.55 | E10: 5 | F10: 4.8
A11: 13 In 1 Home Repair Tools Box Kit Set | B11: 1600 | C11: 2929 | D11: 0.45 | E11: 5 | F11: 3.8
A12: Genebre 115 In 1 Screwdriver Repairing Tool Set For IPhone Cellphone Hand Tool | B12: 799 | C12: 999 | D12: 0.2 | E12: 12 | F12: 4.1
A13: 100 Pcs Crochet Hook Tool Set Knitting Hook Set With Box | B13: 990 | C13: 1500 | D13: 0.34 | E13: 39 | F13: 4.7
... A22: 3PCS Single Head Knitting Crochet Sweater Needle Set | B22: 38 | C22: 80 | D22: 0.53 | E22: 13 | F22: 3.3
A23: 4pcs Bathroom/Kitchen Towel Rack,Roll Paper Holder,Towel Bars,Hook | B23: 1860 | C23: 3220 | D23: 0.42
A24: LED Romantic Spaceship Starry Sky Projector,Children's Bedroom Night Light-Blue | B24: 880 | C24: 1350 | D24: 0.35 | E24: 6 | F24: 4
A25: Foldable Overbed Table/Desk | B25: 1650 | C25: 2150 | D25: 0.23 | E25: 14 | F25: 4.4
A26: LASA 3 Tier Bamboo Shoe Bench Storage Shelf | B26: 2048 | C26: 4500 | D26: 0.54 | E26: 7 | F26: 4.3
A27: Electronic Digital Display Vernier Caliper | B27: 420 | C27: 647 | D27: 0.35 | E27: 49 | F27: 4.6
A28: Portable Wardrobe Nonwoven With 3 Hanging Rods And 6 Storage Shelves | B28: 2880 | C28: 3520 | D28: 0.18 | E28: 12 | F28: 3.8
A29: 12 Litre Black Insulated Lunch Box | B29: 1350 | C29: 1990 | D29: 0.32 | E29: 13 | F29: 3.8
A30: 52 Pieces Cake Decorating Tool Set Gift Kit Baking Supplies | B30: 1758 | C30: 2499 | D30: 0.3 | E30: 20 | F30: 4.1
A31: MultiFunctional Storage Rack Multi-layer Bookshelf | B31: 2200 | C31: 4080 | D31: 0.46
A32: Exfoliate And Exfoliate Face Towel - Black | B32: 185 | C32: 382 | D32: 0.52 | E32: 9 | F32: 4.3
A33: 12 Litre Insulated Lunch Box Grey | B33: 980 | C33: 1490 | D33: 0.34 | E33: 12 | F33: 4.7
A34: LED Eye Protection Desk Lamp , Study, Reading, USB Fan - Double Pen Holder | B34: 1820 | C34: 3490 | D34: 0.48 | E34: 9 | F34: 4.3
A35: 53Pcs/Set Yarn Knitting Crochet Hooks With Bag - Fortune Cat | B35: 1940 | C35: 2650 | D35: 0.27 | E35: 20 | F35: 4.7
A36: 53 Pieces/Set Yarn Knitting Crochet Hooks With Bag - Pansies | B36: 1980 | C36: 2699 | D36: 0.27 | E36: 32 | F36: 4.5
A37: DIY File Folder, Office Drawer File Holder, Pen Holder, Desktop Storage Rack | B37: 1620 | C37: 2690 | D37: 0.4 | E37: 1 | F37: 5
A38: Classic Black Cat Cotton Hemp Pillow Case For Home Car | B38: 171 | C38: 360 | D38: 0.53 | E38: 2 | F38: 5
A39: Punch-free Great Load Bearing Bathroom Storage Rack Wall Shelf-White | B39: 389 | C39: 656 | D39: 0.41 | E39: 36 | F39: 4.3
A40: 1/2/3 Seater Elastic Sofa Cover,Living Room/Home Decor Chair Cover-Grey | B40: 1800 | C40: 2700 | D40: 0.38 | E40: 2 | F40: 4.5
A41: LASA Stainless Steel Double Wall Mount Soap Dispenser - 500ml | B41: 2750 | C41: 4471 | D41: 0.38
A42: 4M Float Switch Water Level Controller -Water Tank | B42: 475 | C42: 931 | D42: 0.49
A43: Modern Sofa Throw Pillow Cover-45x45cm-Blue&Red | B43: 238 | C43: 476 | D43: 0.5
A44: Balloon Insert, Birthday Party Balloon Set, PU Leather | B44: 610 | C44: 1060 | D44: 0.42
A45: Shower Cap Wide Elastic Band Cover Reusable Bashroom Cap | B45: 2132 | C45: 2169 | D45: 0.02
A46: Christmas Elk Fence Yard Lawn Decorations Cute For Holidays | B46: 999 | C46: 2000 | D46: 0.5
A47: 60W Hot Melt Glue Sprayer - Efficient And Stable Glue Dispensing | B47: 1190 | C47: 1785 | D47: 0.33
A48: Car Phone Charging Stand | B48: 671 | C48: 1316 | D48: 0.49
...

Sheet tblProducts
A1: Product | B1: Current Price | C1: Price Category | D1: Old Price | E1: Discount | F1: Discount Category | G1: Discount Amount | H1: Review | I1: Rating | J1: Rating Category | K1: Validation Check
A2: 115 Piece Set Of Multifunctional Precision Screwdrivers | B2: 950 | C2: =IF(Table3[[#This Row],[Current Price]]="","Missing",IF(Table3[[#This Row],[Current Price]]<=Price_Q1,"Low Price",IF(Table3[[#This Row],[Current Price]]<=Price_Q3,"Medium Price","High Price"))) -> Medium Price | D2: 1525 | E2: 0.38 | F2: =IF(Table3[[#This Row],[Discount]]="","Missing",IF(Table3[[#This Row],[Discount]]<0.2,"Low Discount",IF(Table3[[#This Row],[Discount]]<=0.4,"Medium Discount","High Discount"))) -> Medium Discount | G2: =Table3[[#This Row],[Old Price]]-Table3[[#This Row],[Current Price]] -> 575 | H2: 2 | I2: 4.5 | J2: =IF(Table3[[#This Row],[Rating]]="","Missing",IF(Table3[[#This Row],[Rating]]<3,"Poor",IF(Table3[[#This Row],[Rating]]<=4.5,"Average","Excellent"))) -> Average | K2: =IF(OR(Table3[[#This Row],[Rating]]<0,Table3[[#This Row],[Rating]]>5),"Check rating",IF(OR(Table3[[#This Row],[Discount]]<0,Table3[[#This Row],[Discount]]>1),"Check discount",IF(Table3[[#This Row],[Current Price]]>Table3[[#This Row],[Old Price]],"Check prices","OK"))) -> OK
A3: Metal Decorative Hooks Key Hangers Entryway Wall Hooks Towel Hooks - Home | B3: 527 | C3: =IF(Table3[[#This Row],[Current Price]]="","Missing",IF(Table3[[#This Row],[Current Price]]<=Price_Q1,"Low Price",IF(Table3[[#This Row],[Current Price]]<=Price_Q3,"Medium Price","High Price"))) -> Medium Price | D3: 999 | E3: 0.47 | F3: =IF(Table3[[#This Row],[Discount]]="","Missing",IF(Table3[[#This Row],[Discount]]<0.2,"Low Discount",IF(Table3[[#This Row],[Discount]]<=0.4,"Medium Discount","High Discount"))) -> High Discount | G3: =Table3[[#This Row],[Old Price]]-Table3[[#This Row],[Current Price]] -> 472 | H3: 14 | I3: 4.1 | J3: =IF(Table3[[#This Row],[Rating]]="","Missing",IF(Table3[[#This Row],[Rating]]<3,"Poor",IF(Table3[[#This Row],[Rating]]<=4.5,"Average","Excellent"))) -> Average | K3: =IF(OR(Table3[[#This Row],[Rating]]<0,Table3[[#This Row],[Rating]]>5),"Check rating",IF(OR(Table3[[#This Row],[Discount]]<0,Table3[[#This Row],[Discount]]>1),"Check discount",IF(Table3[[#This Row],[Current Price]]>Table3[[#This Row],[Old Price]],"Check prices","OK"))) -> OK
A4: Portable Mini Cordless Car Vacuum Cleaner - Blue | B4: 2199 | C4: =IF(Table3[[#This Row],[Current Price]]="","Missing",IF(Table3[[#This Row],[Current Price]]<=Price_Q1,"Low Price",IF(Table3[[#This Row],[Current Price]]<=Price_Q3,"Medium Price","High Price"))) -> High Price | D4: 2923 | E4: 0.25 | F4: =IF(Table3[[#This Row],[Discount]]="","Missing",IF(Table3[[#This Row],[Discount]]<0.2,"Low Discount",IF(Table3[[#This Row],[Discount]]<=0.4,"Medium Discount","High Discount"))) -> Medium Discount | G4: =Table3[[#This Row],[Old Price]]-Table3[[#This Row],[Current Price]] -> 724 | H4: 24 | I4: 4.6 | J4: =IF(Table3[[#This Row],[Rating]]="","Missing",IF(Table3[[#This Row],[Rating]]<3,"Poor",IF(Table3[[#This Row],[Rating]]<=4.5,"Average","Excellent"))) -> Excellent | K4: =IF(OR(Table3[[#This Row],[Rating]]<0,Table3[[#This Row],[Rating]]>5),"Check rating",IF(OR(Table3[[#This Row],[Discount]]<0,Table3[[#This Row],[Discount]]>1),"Check discount",IF(Table3[[#This Row],[Current Price]]>Table3[[#This Row],[Old Price]],"Check prices","OK"))) -> OK
A5: Weighing Scale Digital Bathroom Body Fat Scale USB-Black | B5: 1580 | C5: =IF(Table3[[#This Row],[Current Price]]="","Missing",IF(Table3[[#This Row],[Current Price]]<=Price_Q1,"Low Price",IF(Table3[[#This Row],[Current Price]]<=Price_Q3,"Medium Price","High Price"))) -> Medium Price | D5: 2499 | E5: 0.37 | F5: =IF(Table3[[#This Row],[Discount]]="","Missing",IF(Table3[[#This Row],[Discount]]<0.2,"Low Discount",IF(Table3[[#This Row],[Discount]]<=0.4,"Medium Discount","High Discount"))) -> Medium Discount | G5: =Table3[[#This Row],[Old Price]]-Table3[[#This Row],[Current Price]] -> 919 | H5: 7 | I5: 4.7 | J5: =IF(Table3[[#This Row],[Rating]]="","Missing",IF(Table3[[#This Row],[Rating]]<3,"Poor",IF(Table3[[#This Row],[Rating]]<=4.5,"Average","Excellent"))) -> Excellent | K5: =IF(OR(Table3[[#This Row],[Rating]]<0,Table3[[#This Row],[Rating]]>5),"Check rating",IF(OR(Table3[[#This Row],[Discount]]<0,Table3[[#This Row],[Discount]]>1),"Check discount",IF(Table3[[#This Row],[Current Price]]>Table3[[#This Row],[Old Price]],"Check prices","OK"))) -> OK
A6: Portable Home Small Air Humidifier 3-Speed Fan - Green | B6: 1740 | C6: =IF(Table3[[#This Row],[Current Price]]="","Missing",IF(Table3[[#This Row],[Current Price]]<=Price_Q1,"Low Price",IF(Table3[[#This Row],[Current Price]]<=Price_Q3,"Medium Price","High Price"))) -> High Price | D6: 2356 | E6: 0.26 | F6: =IF(Table3[[#This Row],[Discount]]="","Missing",IF(Table3[[#This Row],[Discount]]<0.2,"Low Discount",IF(Table3[[#This Row],[Discount]]<=0.4,"Medium Discount","High Discount"))) -> Medium Discount | G6: =Table3[[#This Row],[Old Price]]-Table3[[#This Row],[Current Price]] -> 616 | H6: 5 | I6: 4.8 | J6: =IF(Table3[[#This Row],[Rating]]="","Missing",IF(Table3[[#This Row],[Rating]]<3,"Poor",IF(Table3[[#This Row],[Rating]]<=4.5,"Average","Excellent"))) -> Excellent | K6: =IF(OR(Table3[[#This Row],[Rating]]<0,Table3[[#This Row],[Rating]]>5),"Check rating",IF(OR(Table3[[#This Row],[Discount]]<0,Table3[[#This Row],[Discount]]>1),"Check discount",IF(Table3[[#This Row],[Current Price]]>Table3[[#This Row],[Old Price]],"Check prices","OK"))) -> OK
A7: 220V 60W Electric Soldering Iron Kits With Tools, Tips, And Multimeter | B7: 2999 | C7: =IF(Table3[[#This Row],[Current Price]]="","Missing",IF(Table3[[#This Row],[Current Price]]<=Price_Q1,"Low Price",IF(Table3[[#This Row],[Current Price]]<=Price_Q3,"Medium Price","High Price"))) -> High Price | D7: 3290 | E7: 0.09 | F7: =IF(Table3[[#This Row],[Discount]]="","Missing",IF(Table3[[#This Row],[Discount]]<0.2,"Low Discount",IF(Table3[[#This Row],[Discount]]<=0.4,"Medium Discount","High Discount"))) -> Low Discount | G7: =Table3[[#This Row],[Old Price]]-Table3[[#This Row],[Current Price]] -> 291 | H7: 15 | I7: 4 | J7: =IF(Table3[[#This Row],[Rating]]="","Missing",IF(Table3[[#This Row],[Rating]]<3,"Poor",IF(Table3[[#This Row],[Rating]]<=4.5,"Average","Excellent"))) -> Average | K7: =IF(OR(Table3[[#This Row],[Rating]]<0,Table3[[#This Row],[Rating]]>5),"Check rating",IF(OR(Table3[[#This Row],[Discount]]<0,Table3[[#This Row],[Discount]]>1),"Check discount",IF(Table3[[#This Row],[Current Price]]>Table3[[#This Row],[Old Price]],"Check prices","OK"))) -> OK
A8: 137 Pieces Cake Decorating Tool Set Baking Supplies | B8: 2319 | C8: =IF(Table3[[#This Row],[Current Price]]="","Missing",IF(Table3[[#This Row],[Current Price]]<=Price_Q1,"Low Price",IF(Table3[[#This Row],[Current Price]]<=Price_Q3,"Medium Price","High Price"))) -> High Price | D8: 3032 | E8: 0.24 | F8: =IF(Table3[[#This Row],[Discount]]="","Missing",IF(Table3[[#This Row],[Discount]]<0.2,"Low Discount",IF(Table3[[#This Row],[Discount]]<=0.4,"Medium Discount","High Discount"))) -> Medium Discount | G8: =Table3[[#This Row],[Old Price]]-Table3[[#This Row],[Current Price]] -> 713 | H8: 55 | I8: 4.6 | J8: =IF(Table3[[#This Row],[Rating]]="","Missing",IF(Table3[[#This Row],[Rating]]<3,"Poor",IF(Table3[[#This Row],[Rating]]<=4.5,"Average","Excellent"))) -> Excellent | K8: =IF(OR(Table3[[#This Row],[Rating]]<0,Table3[[#This Row],[Rating]]>5),"Check rating",IF(OR(Table3[[#This Row],[Discount]]<0,Table3[[#This Row],[Discount]]>1),"Check discount",IF(Table3[[#This Row],[Current Price]]>Table3[[#This Row],[Old Price]],"Check prices","OK"))) -> OK
A9: Desk Foldable Fan Adjustable Fan Strong Wind 3 Gear Usb | B9: 988 | C9: =IF(Table3[[#This Row],[Current Price]]="","Missing",IF(Table3[[#This Row],[Current Price]]<=Price_Q1,"Low Price",IF(Table3[[#This Row],[Current Price]]<=Price_Q3,"Medium Price","High Price"))) -> Medium Price | D9: 1580 | E9: 0.37 | F9: =IF(Table3[[#This Row],[Discount]]="","Missing",IF(Table3[[#This Row],[Discount]]<0.2,"Low Discount",IF(Table3[[#This Row],[Discount]]<=0.4,"Medium Discount","High Discount"))) -> Medium Discount | G9: =Table3[[#This Row],[Old Price]]-Table3[[#This Row],[Current Price]] -> 592 | H9: 2 | I9: 4 | J9: =IF(Table3[[#This Row],[Rating]]="","Missing",IF(Table3[[#This Row],[Rating]]<3,"Poor",IF(Table3[[#This Row],[Rating]]<=4.5,"Average","Excellent"))) -> Average | K9: =IF(OR(Table3[[#This Row],[Rating]]<0,Table3[[#This Row],[Rating]]>5),"Check rating",IF(OR(Table3[[#This Row],[Discount]]<0,Table3[[#This Row],[Discount]]>1),"Check discount",IF(Table3[[#This Row],[Current Price]]>Table3[[#This Row],[Old Price]],"Check prices","OK"))) -> OK
A10: LASA FOLDING TABLE SERVING STAND | B10: 1274 | C10: =IF(Table3[[#This Row],[Current Price]]="","Missing",IF(Table3[[#This Row],[Current Price]]<=Price_Q1,"Low Price",IF(Table3[[#This Row],[Current Price]]<=Price_Q3,"Medium Price","High Price"))) -> Medium Price | D10: 2800 | E10: 0.55 | F10: =IF(Table3[[#This Row],[Discount]]="","Missing",IF(Table3[[#This Row],[Discount]]<0.2,"Low Discount",IF(Table3[[#This Row],[Discount]]<=0.4,"Medium Discount","High Discount"))) -> High Discount | G10: =Table3[[#This Row],[Old Price]]-Table3[[#This Row],[Current Price]] -> 1526 | H10: 5 | I10: 4.8 | J10: =IF(Table3[[#This Row],[Rating]]="","Missing",IF(Table3[[#This Row],[Rating]]<3,"Poor",IF(Table3[[#This Row],[Rating]]<=4.5,"Average","Excellent"))) -> Excellent | K10: =IF(OR(Table3[[#This Row],[Rating]]<0,Table3[[#This Row],[Rating]]>5),"Check rating",IF(OR(Table3[[#This Row],[Discount]]<0,Table3[[#This Row],[Discount]]>1),"Check discount",IF(Table3[[#This Row],[Current Price]]>Table3[[#This Row],[Old Price]],"Check prices","OK"))) -> OK
A11: 13 In 1 Home Repair Tools Box Kit Set | B11: 1600 | C11: =IF(Table3[[#This Row],[Current Price]]="","Missing",IF(Table3[[#This Row],[Current Price]]<=Price_Q1,"Low Price",IF(Table3[[#This Row],[Current Price]]<=Price_Q3,"Medium Price","High Price"))) -> Medium Price | D11: 2929 | E11: 0.45 | F11: =IF(Table3[[#This Row],[Discount]]="","Missing",IF(Table3[[#This Row],[Discount]]<0.2,"Low Discount",IF(Table3[[#This Row],[Discount]]<=0.4,"Medium Discount","High Discount"))) -> High Discount | G11: =Table3[[#This Row],[Old Price]]-Table3[[#This Row],[Current Price]] -> 1329 | H11: 5 | I11: 3.8 | J11: =IF(Table3[[#This Row],[Rating]]="","Missing",IF(Table3[[#This Row],[Rating]]<3,"Poor",IF(Table3[[#This Row],[Rating]]<=4.5,"Average","Excellent"))) -> Average | K11: =IF(OR(Table3[[#This Row],[Rating]]<0,Table3[[#This Row],[Rating]]>5),"Check rating",IF(OR(Table3[[#This Row],[Discount]]<0,Table3[[#This Row],[Discount]]>1),"Check discount",IF(Table3[[#This Row],[Current Price]]>Table3[[#This Row],[Old Price]],"Check prices","OK"))) -> OK
A12: Genebre 115 In 1 Screwdriver Repairing Tool Set For IPhone Cellphone Hand Tool | B12: 799 | C12: =IF(Table3[[#This Row],[Current Price]]="","Missing",IF(Table3[[#This Row],[Current Price]]<=Price_Q1,"Low Price",IF(Table3[[#This Row],[Current Price]]<=Price_Q3,"Medium Price","High Price"))) -> Medium Price | D12: 999 | E12: 0.2 | F12: =IF(Table3[[#This Row],[Discount]]="","Missing",IF(Table3[[#This Row],[Discount]]<0.2,"Low Discount",IF(Table3[[#This Row],[Discount]]<=0.4,"Medium Discount","High Discount"))) -> Medium Discount | G12: =Table3[[#This Row],[Old Price]]-Table3[[#This Row],[Current Price]] -> 200 | H12: 12 | I12: 4.1 | J12: =IF(Table3[[#This Row],[Rating]]="","Missing",IF(Table3[[#This Row],[Rating]]<3,"Poor",IF(Table3[[#This Row],[Rating]]<=4.5,"Average","Excellent"))) -> Average | K12: =IF(OR(Table3[[#This Row],[Rating]]<0,Table3[[#This Row],[Rating]]>5),"Check rating",IF(OR(Table3[[#This Row],[Discount]]<0,Table3[[#This Row],[Discount]]>1),"Check discount",IF(Table3[[#This Row],[Current Price]]>Table3[[#This Row],[Old Price]],"Check prices","OK"))) -> OK
A13: 100 Pcs Crochet Hook Tool Set Knitting Hook Set With Box | B13: 990 | C13: =IF(Table3[[#This Row],[Current Price]]="","Missing",IF(Table3[[#This Row],[Current Price]]<=Price_Q1,"Low Price",IF(Table3[[#This Row],[Current Price]]<=Price_Q3,"Medium Price","High Price"))) -> Medium Price | D13: 1500 | E13: 0.34 | F13: =IF(Table3[[#This Row],[Discount]]="","Missing",IF(Table3[[#This Row],[Discount]]<0.2,"Low Discount",IF(Table3[[#This Row],[Discount]]<=0.4,"Medium Discount","High Discount"))) -> Medium Discount | G13: =Table3[[#This Row],[Old Price]]-Table3[[#This Row],[Current Price]] -> 510 | H13: 39 | I13: 4.7 | J13: =IF(Table3[[#This Row],[Rating]]="","Missing",IF(Table3[[#This Row],[Rating]]<3,"Poor",IF(Table3[[#This Row],[Rating]]<=4.5,"Average","Excellent"))) -> Excellent | K13: =IF(OR(Table3[[#This Row],[Rating]]<0,Table3[[#This Row],[Rating]]>5),"Check rating",IF(OR(Table3[[#This Row],[Discount]]<0,Table3[[#This Row],[Discount]]>1),"Check discount",IF(Table3[[#This Row],[Current Price]]>Table3[[#This Row],[Old Price]],"Check prices","OK"))) -> OK
... A22: 3PCS Single Head Knitting Crochet Sweater Needle Set | B22: 38 | C22: =IF(Table3[[#This Row],[Current Price]]="","Missing",IF(Table3[[#This Row],[Current Price]]<=Price_Q1,"Low Price",IF(Table3[[#This Row],[Current Price]]<=Price_Q3,"Medium Price","High Price"))) -> Low Price | D22: 80 | E22: 0.53 | F22: =IF(Table3[[#This Row],[Discount]]="","Missing",IF(Table3[[#This Row],[Discount]]<0.2,"Low Discount",IF(Table3[[#This Row],[Discount]]<=0.4,"Medium Discount","High Discount"))) -> High Discount | G22: =Table3[[#This Row],[Old Price]]-Table3[[#This Row],[Current Price]] -> 42 | H22: 13 | I22: 3.3 | J22: =IF(Table3[[#This Row],[Rating]]="","Missing",IF(Table3[[#This Row],[Rating]]<3,"Poor",IF(Table3[[#This Row],[Rating]]<=4.5,"Average","Excellent"))) -> Average | K22: =IF(OR(Table3[[#This Row],[Rating]]<0,Table3[[#This Row],[Rating]]>5),"Check rating",IF(OR(Table3[[#This Row],[Discount]]<0,Table3[[#This Row],[Discount]]>1),"Check discount",IF(Table3[[#This Row],[Current Price]]>Table3[[#This Row],[Old Price]],"Check prices","OK"))) -> OK
A23: 4pcs Bathroom/Kitchen Towel Rack,Roll Paper Holder,Towel Bars,Hook | B23: 1860 | C23: =IF(Table3[[#This Row],[Current Price]]="","Missing",IF(Table3[[#This Row],[Current Price]]<=Price_Q1,"Low Price",IF(Table3[[#This Row],[Current Price]]<=Price_Q3,"Medium Price","High Price"))) -> High Price | D23: 3220 | E23: 0.42 | F23: =IF(Table3[[#This Row],[Discount]]="","Missing",IF(Table3[[#This Row],[Discount]]<0.2,"Low Discount",IF(Table3[[#This Row],[Discount]]<=0.4,"Medium Discount","High Discount"))) -> High Discount | G23: =Table3[[#This Row],[Old Price]]-Table3[[#This Row],[Current Price]] -> 1360 | J23: =IF(Table3[[#This Row],[Rating]]="","Missing",IF(Table3[[#This Row],[Rating]]<3,"Poor",IF(Table3[[#This Row],[Rating]]<=4.5,"Average","Excellent"))) -> Missing | K23: =IF(OR(Table3[[#This Row],[Rating]]<0,Table3[[#This Row],[Rating]]>5),"Check rating",IF(OR(Table3[[#This Row],[Discount]]<0,Table3[[#This Row],[Discount]]>1),"Check discount",IF(Table3[[#This Row],[Current Price]]>Table3[[#This Row],[Old Price]],"Check prices","OK"))) -> Check rating
A24: LED Romantic Spaceship Starry Sky Projector,Children's Bedroom Night Light-Blue | B24: 880 | C24: =IF(Table3[[#This Row],[Current Price]]="","Missing",IF(Table3[[#This Row],[Current Price]]<=Price_Q1,"Low Price",IF(Table3[[#This Row],[Current Price]]<=Price_Q3,"Medium Price","High Price"))) -> Medium Price | D24: 1350 | E24: 0.35 | F24: =IF(Table3[[#This Row],[Discount]]="","Missing",IF(Table3[[#This Row],[Discount]]<0.2,"Low Discount",IF(Table3[[#This Row],[Discount]]<=0.4,"Medium Discount","High Discount"))) -> Medium Discount | G24: =Table3[[#This Row],[Old Price]]-Table3[[#This Row],[Current Price]] -> 470 | H24: 6 | I24: 4 | J24: =IF(Table3[[#This Row],[Rating]]="","Missing",IF(Table3[[#This Row],[Rating]]<3,"Poor",IF(Table3[[#This Row],[Rating]]<=4.5,"Average","Excellent"))) -> Average | K24: =IF(OR(Table3[[#This Row],[Rating]]<0,Table3[[#This Row],[Rating]]>5),"Check rating",IF(OR(Table3[[#This Row],[Discount]]<0,Table3[[#This Row],[Discount]]>1),"Check discount",IF(Table3[[#This Row],[Current Price]]>Table3[[#This Row],[Old Price]],"Check prices","OK"))) -> OK
A25: Foldable Overbed Table/Desk | B25: 1650 | C25: =IF(Table3[[#This Row],[Current Price]]="","Missing",IF(Table3[[#This Row],[Current Price]]<=Price_Q1,"Low Price",IF(Table3[[#This Row],[Current Price]]<=Price_Q3,"Medium Price","High Price"))) -> Medium Price | D25: 2150 | E25: 0.23 | F25: =IF(Table3[[#This Row],[Discount]]="","Missing",IF(Table3[[#This Row],[Discount]]<0.2,"Low Discount",IF(Table3[[#This Row],[Discount]]<=0.4,"Medium Discount","High Discount"))) -> Medium Discount | G25: =Table3[[#This Row],[Old Price]]-Table3[[#This Row],[Current Price]] -> 500 | H25: 14 | I25: 4.4 | J25: =IF(Table3[[#This Row],[Rating]]="","Missing",IF(Table3[[#This Row],[Rating]]<3,"Poor",IF(Table3[[#This Row],[Rating]]<=4.5,"Average","Excellent"))) -> Average | K25: =IF(OR(Table3[[#This Row],[Rating]]<0,Table3[[#This Row],[Rating]]>5),"Check rating",IF(OR(Table3[[#This Row],[Discount]]<0,Table3[[#This Row],[Discount]]>1),"Check discount",IF(Table3[[#This Row],[Current Price]]>Table3[[#This Row],[Old Price]],"Check prices","OK"))) -> OK
A26: LASA 3 Tier Bamboo Shoe Bench Storage Shelf | B26: 2048 | C26: =IF(Table3[[#This Row],[Current Price]]="","Missing",IF(Table3[[#This Row],[Current Price]]<=Price_Q1,"Low Price",IF(Table3[[#This Row],[Current Price]]<=Price_Q3,"Medium Price","High Price"))) -> High Price | D26: 4500 | E26: 0.54 | F26: =IF(Table3[[#This Row],[Discount]]="","Missing",IF(Table3[[#This Row],[Discount]]<0.2,"Low Discount",IF(Table3[[#This Row],[Discount]]<=0.4,"Medium Discount","High Discount"))) -> High Discount | G26: =Table3[[#This Row],[Old Price]]-Table3[[#This Row],[Current Price]] -> 2452 | H26: 7 | I26: 4.3 | J26: =IF(Table3[[#This Row],[Rating]]="","Missing",IF(Table3[[#This Row],[Rating]]<3,"Poor",IF(Table3[[#This Row],[Rating]]<=4.5,"Average","Excellent"))) -> Average | K26: =IF(OR(Table3[[#This Row],[Rating]]<0,Table3[[#This Row],[Rating]]>5),"Check rating",IF(OR(Table3[[#This Row],[Discount]]<0,Table3[[#This Row],[Discount]]>1),"Check discount",IF(Table3[[#This Row],[Current Price]]>Table3[[#This Row],[Old Price]],"Check prices","OK"))) -> OK
A27: Electronic Digital Display Vernier Caliper | B27: 420 | C27: =IF(Table3[[#This Row],[Current Price]]="","Missing",IF(Table3[[#This Row],[Current Price]]<=Price_Q1,"Low Price",IF(Table3[[#This Row],[Current Price]]<=Price_Q3,"Medium Price","High Price"))) -> Low Price | D27: 647 | E27: 0.35 | F27: =IF(Table3[[#This Row],[Discount]]="","Missing",IF(Table3[[#This Row],[Discount]]<0.2,"Low Discount",IF(Table3[[#This Row],[Discount]]<=0.4,"Medium Discount","High Discount"))) -> Medium Discount | G27: =Table3[[#This Row],[Old Price]]-Table3[[#This Row],[Current Price]] -> 227 | H27: 49 | I27: 4.6 | J27: =IF(Table3[[#This Row],[Rating]]="","Missing",IF(Table3[[#This Row],[Rating]]<3,"Poor",IF(Table3[[#This Row],[Rating]]<=4.5,"Average","Excellent"))) -> Excellent | K27: =IF(OR(Table3[[#This Row],[Rating]]<0,Table3[[#This Row],[Rating]]>5),"Check rating",IF(OR(Table3[[#This Row],[Discount]]<0,Table3[[#This Row],[Discount]]>1),"Check discount",IF(Table3[[#This Row],[Current Price]]>Table3[[#This Row],[Old Price]],"Check prices","OK"))) -> OK
A28: Portable Wardrobe Nonwoven With 3 Hanging Rods And 6 Storage Shelves | B28: 2880 | C28: =IF(Table3[[#This Row],[Current Price]]="","Missing",IF(Table3[[#This Row],[Current Price]]<=Price_Q1,"Low Price",IF(Table3[[#This Row],[Current Price]]<=Price_Q3,"Medium Price","High Price"))) -> High Price | D28: 3520 | E28: 0.18 | F28: =IF(Table3[[#This Row],[Discount]]="","Missing",IF(Table3[[#This Row],[Discount]]<0.2,"Low Discount",IF(Table3[[#This Row],[Discount]]<=0.4,"Medium Discount","High Discount"))) -> Low Discount | G28: =Table3[[#This Row],[Old Price]]-Table3[[#This Row],[Current Price]] -> 640 | H28: 12 | I28: 3.8 | J28: =IF(Table3[[#This Row],[Rating]]="","Missing",IF(Table3[[#This Row],[Rating]]<3,"Poor",IF(Table3[[#This Row],[Rating]]<=4.5,"Average","Excellent"))) -> Average | K28: =IF(OR(Table3[[#This Row],[Rating]]<0,Table3[[#This Row],[Rating]]>5),"Check rating",IF(OR(Table3[[#This Row],[Discount]]<0,Table3[[#This Row],[Discount]]>1),"Check discount",IF(Table3[[#This Row],[Current Price]]>Table3[[#This Row],[Old Price]],"Check prices","OK"))) -> OK
A29: 12 Litre Black Insulated Lunch Box | B29: 1350 | C29: =IF(Table3[[#This Row],[Current Price]]="","Missing",IF(Table3[[#This Row],[Current Price]]<=Price_Q1,"Low Price",IF(Table3[[#This Row],[Current Price]]<=Price_Q3,"Medium Price","High Price"))) -> Medium Price | D29: 1990 | E29: 0.32 | F29: =IF(Table3[[#This Row],[Discount]]="","Missing",IF(Table3[[#This Row],[Discount]]<0.2,"Low Discount",IF(Table3[[#This Row],[Discount]]<=0.4,"Medium Discount","High Discount"))) -> Medium Discount | G29: =Table3[[#This Row],[Old Price]]-Table3[[#This Row],[Current Price]] -> 640 | H29: 13 | I29: 3.8 | J29: =IF(Table3[[#This Row],[Rating]]="","Missing",IF(Table3[[#This Row],[Rating]]<3,"Poor",IF(Table3[[#This Row],[Rating]]<=4.5,"Average","Excellent"))) -> Average | K29: =IF(OR(Table3[[#This Row],[Rating]]<0,Table3[[#This Row],[Rating]]>5),"Check rating",IF(OR(Table3[[#This Row],[Discount]]<0,Table3[[#This Row],[Discount]]>1),"Check discount",IF(Table3[[#This Row],[Current Price]]>Table3[[#This Row],[Old Price]],"Check prices","OK"))) -> OK
A30: 52 Pieces Cake Decorating Tool Set Gift Kit Baking Supplies | B30: 1758 | C30: =IF(Table3[[#This Row],[Current Price]]="","Missing",IF(Table3[[#This Row],[Current Price]]<=Price_Q1,"Low Price",IF(Table3[[#This Row],[Current Price]]<=Price_Q3,"Medium Price","High Price"))) -> High Price | D30: 2499 | E30: 0.3 | F30: =IF(Table3[[#This Row],[Discount]]="","Missing",IF(Table3[[#This Row],[Discount]]<0.2,"Low Discount",IF(Table3[[#This Row],[Discount]]<=0.4,"Medium Discount","High Discount"))) -> Medium Discount | G30: =Table3[[#This Row],[Old Price]]-Table3[[#This Row],[Current Price]] -> 741 | H30: 20 | I30: 4.1 | J30: =IF(Table3[[#This Row],[Rating]]="","Missing",IF(Table3[[#This Row],[Rating]]<3,"Poor",IF(Table3[[#This Row],[Rating]]<=4.5,"Average","Excellent"))) -> Average | K30: =IF(OR(Table3[[#This Row],[Rating]]<0,Table3[[#This Row],[Rating]]>5),"Check rating",IF(OR(Table3[[#This Row],[Discount]]<0,Table3[[#This Row],[Discount]]>1),"Check discount",IF(Table3[[#This Row],[Current Price]]>Table3[[#This Row],[Old Price]],"Check prices","OK"))) -> OK
A31: MultiFunctional Storage Rack Multi-layer Bookshelf | B31: 2200 | C31: =IF(Table3[[#This Row],[Current Price]]="","Missing",IF(Table3[[#This Row],[Current Price]]<=Price_Q1,"Low Price",IF(Table3[[#This Row],[Current Price]]<=Price_Q3,"Medium Price","High Price"))) -> High Price | D31: 4080 | E31: 0.46 | F31: =IF(Table3[[#This Row],[Discount]]="","Missing",IF(Table3[[#This Row],[Discount]]<0.2,"Low Discount",IF(Table3[[#This Row],[Discount]]<=0.4,"Medium Discount","High Discount"))) -> High Discount | G31: =Table3[[#This Row],[Old Price]]-Table3[[#This Row],[Current Price]] -> 1880 | J31: =IF(Table3[[#This Row],[Rating]]="","Missing",IF(Table3[[#This Row],[Rating]]<3,"Poor",IF(Table3[[#This Row],[Rating]]<=4.5,"Average","Excellent"))) -> Missing | K31: =IF(OR(Table3[[#This Row],[Rating]]<0,Table3[[#This Row],[Rating]]>5),"Check rating",IF(OR(Table3[[#This Row],[Discount]]<0,Table3[[#This Row],[Discount]]>1),"Check discount",IF(Table3[[#This Row],[Current Price]]>Table3[[#This Row],[Old Price]],"Check prices","OK"))) -> Check rating
A32: Exfoliate And Exfoliate Face Towel - Black | B32: 185 | C32: =IF(Table3[[#This Row],[Current Price]]="","Missing",IF(Table3[[#This Row],[Current Price]]<=Price_Q1,"Low Price",IF(Table3[[#This Row],[Current Price]]<=Price_Q3,"Medium Price","High Price"))) -> Low Price | D32: 382 | E32: 0.52 | F32: =IF(Table3[[#This Row],[Discount]]="","Missing",IF(Table3[[#This Row],[Discount]]<0.2,"Low Discount",IF(Table3[[#This Row],[Discount]]<=0.4,"Medium Discount","High Discount"))) -> High Discount | G32: =Table3[[#This Row],[Old Price]]-Table3[[#This Row],[Current Price]] -> 197 | H32: 9 | I32: 4.3 | J32: =IF(Table3[[#This Row],[Rating]]="","Missing",IF(Table3[[#This Row],[Rating]]<3,"Poor",IF(Table3[[#This Row],[Rating]]<=4.5,"Average","Excellent"))) -> Average | K32: =IF(OR(Table3[[#This Row],[Rating]]<0,Table3[[#This Row],[Rating]]>5),"Check rating",IF(OR(Table3[[#This Row],[Discount]]<0,Table3[[#This Row],[Discount]]>1),"Check discount",IF(Table3[[#This Row],[Current Price]]>Table3[[#This Row],[Old Price]],"Check prices","OK"))) -> OK
A33: 12 Litre Insulated Lunch Box Grey | B33: 980 | C33: =IF(Table3[[#This Row],[Current Price]]="","Missing",IF(Table3[[#This Row],[Current Price]]<=Price_Q1,"Low Price",IF(Table3[[#This Row],[Current Price]]<=Price_Q3,"Medium Price","High Price"))) -> Medium Price | D33: 1490 | E33: 0.34 | F33: =IF(Table3[[#This Row],[Discount]]="","Missing",IF(Table3[[#This Row],[Discount]]<0.2,"Low Discount",IF(Table3[[#This Row],[Discount]]<=0.4,"Medium Discount","High Discount"))) -> Medium Discount | G33: =Table3[[#This Row],[Old Price]]-Table3[[#This Row],[Current Price]] -> 510 | H33: 12 | I33: 4.7 | J33: =IF(Table3[[#This Row],[Rating]]="","Missing",IF(Table3[[#This Row],[Rating]]<3,"Poor",IF(Table3[[#This Row],[Rating]]<=4.5,"Average","Excellent"))) -> Excellent | K33: =IF(OR(Table3[[#This Row],[Rating]]<0,Table3[[#This Row],[Rating]]>5),"Check rating",IF(OR(Table3[[#This Row],[Discount]]<0,Table3[[#This Row],[Discount]]>1),"Check discount",IF(Table3[[#This Row],[Current Price]]>Table3[[#This Row],[Old Price]],"Check prices","OK"))) -> OK
A34: LED Eye Protection Desk Lamp , Study, Reading, USB Fan - Double Pen Holder | B34: 1820 | C34: =IF(Table3[[#This Row],[Current Price]]="","Missing",IF(Table3[[#This Row],[Current Price]]<=Price_Q1,"Low Price",IF(Table3[[#This Row],[Current Price]]<=Price_Q3,"Medium Price","High Price"))) -> High Price | D34: 3490 | E34: 0.48 | F34: =IF(Table3[[#This Row],[Discount]]="","Missing",IF(Table3[[#This Row],[Discount]]<0.2,"Low Discount",IF(Table3[[#This Row],[Discount]]<=0.4,"Medium Discount","High Discount"))) -> High Discount | G34: =Table3[[#This Row],[Old Price]]-Table3[[#This Row],[Current Price]] -> 1670 | H34: 9 | I34: 4.3 | J34: =IF(Table3[[#This Row],[Rating]]="","Missing",IF(Table3[[#This Row],[Rating]]<3,"Poor",IF(Table3[[#This Row],[Rating]]<=4.5,"Average","Excellent"))) -> Average | K34: =IF(OR(Table3[[#This Row],[Rating]]<0,Table3[[#This Row],[Rating]]>5),"Check rating",IF(OR(Table3[[#This Row],[Discount]]<0,Table3[[#This Row],[Discount]]>1),"Check discount",IF(Table3[[#This Row],[Current Price]]>Table3[[#This Row],[Old Price]],"Check prices","OK"))) -> OK
A35: 53Pcs/Set Yarn Knitting Crochet Hooks With Bag - Fortune Cat | B35: 1940 | C35: =IF(Table3[[#This Row],[Current Price]]="","Missing",IF(Table3[[#This Row],[Current Price]]<=Price_Q1,"Low Price",IF(Table3[[#This Row],[Current Price]]<=Price_Q3,"Medium Price","High Price"))) -> High Price | D35: 2650 | E35: 0.27 | F35: =IF(Table3[[#This Row],[Discount]]="","Missing",IF(Table3[[#This Row],[Discount]]<0.2,"Low Discount",IF(Table3[[#This Row],[Discount]]<=0.4,"Medium Discount","High Discount"))) -> Medium Discount | G35: =Table3[[#This Row],[Old Price]]-Table3[[#This Row],[Current Price]] -> 710 | H35: 20 | I35: 4.7 | J35: =IF(Table3[[#This Row],[Rating]]="","Missing",IF(Table3[[#This Row],[Rating]]<3,"Poor",IF(Table3[[#This Row],[Rating]]<=4.5,"Average","Excellent"))) -> Excellent | K35: =IF(OR(Table3[[#This Row],[Rating]]<0,Table3[[#This Row],[Rating]]>5),"Check rating",IF(OR(Table3[[#This Row],[Discount]]<0,Table3[[#This Row],[Discount]]>1),"Check discount",IF(Table3[[#This Row],[Current Price]]>Table3[[#This Row],[Old Price]],"Check prices","OK"))) -> OK
A36: 53 Pieces/Set Yarn Knitting Crochet Hooks With Bag - Pansies | B36: 1980 | C36: =IF(Table3[[#This Row],[Current Price]]="","Missing",IF(Table3[[#This Row],[Current Price]]<=Price_Q1,"Low Price",IF(Table3[[#This Row],[Current Price]]<=Price_Q3,"Medium Price","High Price"))) -> High Price | D36: 2699 | E36: 0.27 | F36: =IF(Table3[[#This Row],[Discount]]="","Missing",IF(Table3[[#This Row],[Discount]]<0.2,"Low Discount",IF(Table3[[#This Row],[Discount]]<=0.4,"Medium Discount","High Discount"))) -> Medium Discount | G36: =Table3[[#This Row],[Old Price]]-Table3[[#This Row],[Current Price]] -> 719 | H36: 32 | I36: 4.5 | J36: =IF(Table3[[#This Row],[Rating]]="","Missing",IF(Table3[[#This Row],[Rating]]<3,"Poor",IF(Table3[[#This Row],[Rating]]<=4.5,"Average","Excellent"))) -> Average | K36: =IF(OR(Table3[[#This Row],[Rating]]<0,Table3[[#This Row],[Rating]]>5),"Check rating",IF(OR(Table3[[#This Row],[Discount]]<0,Table3[[#This Row],[Discount]]>1),"Check discount",IF(Table3[[#This Row],[Current Price]]>Table3[[#This Row],[Old Price]],"Check prices","OK"))) -> OK
A37: DIY File Folder, Office Drawer File Holder, Pen Holder, Desktop Storage Rack | B37: 1620 | C37: =IF(Table3[[#This Row],[Current Price]]="","Missing",IF(Table3[[#This Row],[Current Price]]<=Price_Q1,"Low Price",IF(Table3[[#This Row],[Current Price]]<=Price_Q3,"Medium Price","High Price"))) -> Medium Price | D37: 2690 | E37: 0.4 | F37: =IF(Table3[[#This Row],[Discount]]="","Missing",IF(Table3[[#This Row],[Discount]]<0.2,"Low Discount",IF(Table3[[#This Row],[Discount]]<=0.4,"Medium Discount","High Discount"))) -> Medium Discount | G37: =Table3[[#This Row],[Old Price]]-Table3[[#This Row],[Current Price]] -> 1070 | H37: 1 | I37: 5 | J37: =IF(Table3[[#This Row],[Rating]]="","Missing",IF(Table3[[#This Row],[Rating]]<3,"Poor",IF(Table3[[#This Row],[Rating]]<=4.5,"Average","Excellent"))) -> Excellent | K37: =IF(OR(Table3[[#This Row],[Rating]]<0,Table3[[#This Row],[Rating]]>5),"Check rating",IF(OR(Table3[[#This Row],[Discount]]<0,Table3[[#This Row],[Discount]]>1),"Check discount",IF(Table3[[#This Row],[Current Price]]>Table3[[#This Row],[Old Price]],"Check prices","OK"))) -> OK
A38: Classic Black Cat Cotton Hemp Pillow Case For Home Car | B38: 171 | C38: =IF(Table3[[#This Row],[Current Price]]="","Missing",IF(Table3[[#This Row],[Current Price]]<=Price_Q1,"Low Price",IF(Table3[[#This Row],[Current Price]]<=Price_Q3,"Medium Price","High Price"))) -> Low Price | D38: 360 | E38: 0.53 | F38: =IF(Table3[[#This Row],[Discount]]="","Missing",IF(Table3[[#This Row],[Discount]]<0.2,"Low Discount",IF(Table3[[#This Row],[Discount]]<=0.4,"Medium Discount","High Discount"))) -> High Discount | G38: =Table3[[#This Row],[Old Price]]-Table3[[#This Row],[Current Price]] -> 189 | H38: 2 | I38: 5 | J38: =IF(Table3[[#This Row],[Rating]]="","Missing",IF(Table3[[#This Row],[Rating]]<3,"Poor",IF(Table3[[#This Row],[Rating]]<=4.5,"Average","Excellent"))) -> Excellent | K38: =IF(OR(Table3[[#This Row],[Rating]]<0,Table3[[#This Row],[Rating]]>5),"Check rating",IF(OR(Table3[[#This Row],[Discount]]<0,Table3[[#This Row],[Discount]]>1),"Check discount",IF(Table3[[#This Row],[Current Price]]>Table3[[#This Row],[Old Price]],"Check prices","OK"))) -> OK
A39: Punch-free Great Load Bearing Bathroom Storage Rack Wall Shelf-White | B39: 389 | C39: =IF(Table3[[#This Row],[Current Price]]="","Missing",IF(Table3[[#This Row],[Current Price]]<=Price_Q1,"Low Price",IF(Table3[[#This Row],[Current Price]]<=Price_Q3,"Medium Price","High Price"))) -> Low Price | D39: 656 | E39: 0.41 | F39: =IF(Table3[[#This Row],[Discount]]="","Missing",IF(Table3[[#This Row],[Discount]]<0.2,"Low Discount",IF(Table3[[#This Row],[Discount]]<=0.4,"Medium Discount","High Discount"))) -> High Discount | G39: =Table3[[#This Row],[Old Price]]-Table3[[#This Row],[Current Price]] -> 267 | H39: 36 | I39: 4.3 | J39: =IF(Table3[[#This Row],[Rating]]="","Missing",IF(Table3[[#This Row],[Rating]]<3,"Poor",IF(Table3[[#This Row],[Rating]]<=4.5,"Average","Excellent"))) -> Average | K39: =IF(OR(Table3[[#This Row],[Rating]]<0,Table3[[#This Row],[Rating]]>5),"Check rating",IF(OR(Table3[[#This Row],[Discount]]<0,Table3[[#This Row],[Discount]]>1),"Check discount",IF(Table3[[#This Row],[Current Price]]>Table3[[#This Row],[Old Price]],"Check prices","OK"))) -> OK
A40: 1/2/3 Seater Elastic Sofa Cover,Living Room/Home Decor Chair Cover-Grey | B40: 1800 | C40: =IF(Table3[[#This Row],[Current Price]]="","Missing",IF(Table3[[#This Row],[Current Price]]<=Price_Q1,"Low Price",IF(Table3[[#This Row],[Current Price]]<=Price_Q3,"Medium Price","High Price"))) -> High Price | D40: 2700 | E40: 0.38 | F40: =IF(Table3[[#This Row],[Discount]]="","Missing",IF(Table3[[#This Row],[Discount]]<0.2,"Low Discount",IF(Table3[[#This Row],[Discount]]<=0.4,"Medium Discount","High Discount"))) -> Medium Discount | G40: =Table3[[#This Row],[Old Price]]-Table3[[#This Row],[Current Price]] -> 900 | H40: 2 | I40: 4.5 | J40: =IF(Table3[[#This Row],[Rating]]="","Missing",IF(Table3[[#This Row],[Rating]]<3,"Poor",IF(Table3[[#This Row],[Rating]]<=4.5,"Average","Excellent"))) -> Average | K40: =IF(OR(Table3[[#This Row],[Rating]]<0,Table3[[#This Row],[Rating]]>5),"Check rating",IF(OR(Table3[[#This Row],[Discount]]<0,Table3[[#This Row],[Discount]]>1),"Check discount",IF(Table3[[#This Row],[Current Price]]>Table3[[#This Row],[Old Price]],"Check prices","OK"))) -> OK
A41: LASA Stainless Steel Double Wall Mount Soap Dispenser - 500ml | B41: 2750 | C41: =IF(Table3[[#This Row],[Current Price]]="","Missing",IF(Table3[[#This Row],[Current Price]]<=Price_Q1,"Low Price",IF(Table3[[#This Row],[Current Price]]<=Price_Q3,"Medium Price","High Price"))) -> High Price | D41: 4471 | E41: 0.38 | F41: =IF(Table3[[#This Row],[Discount]]="","Missing",IF(Table3[[#This Row],[Discount]]<0.2,"Low Discount",IF(Table3[[#This Row],[Discount]]<=0.4,"Medium Discount","High Discount"))) -> Medium Discount | G41: =Table3[[#This Row],[Old Price]]-Table3[[#This Row],[Current Price]] -> 1721 | J41: =IF(Table3[[#This Row],[Rating]]="","Missing",IF(Table3[[#This Row],[Rating]]<3,"Poor",IF(Table3[[#This Row],[Rating]]<=4.5,"Average","Excellent"))) -> Missing | K41: =IF(OR(Table3[[#This Row],[Rating]]<0,Table3[[#This Row],[Rating]]>5),"Check rating",IF(OR(Table3[[#This Row],[Discount]]<0,Table3[[#This Row],[Discount]]>1),"Check discount",IF(Table3[[#This Row],[Current Price]]>Table3[[#This Row],[Old Price]],"Check prices","OK"))) -> Check rating
A42: 4M Float Switch Water Level Controller -Water Tank | B42: 475 | C42: =IF(Table3[[#This Row],[Current Price]]="","Missing",IF(Table3[[#This Row],[Current Price]]<=Price_Q1,"Low Price",IF(Table3[[#This Row],[Current Price]]<=Price_Q3,"Medium Price","High Price"))) -> Low Price | D42: 931 | E42: 0.49 | F42: =IF(Table3[[#This Row],[Discount]]="","Missing",IF(Table3[[#This Row],[Discount]]<0.2,"Low Discount",IF(Table3[[#This Row],[Discount]]<=0.4,"Medium Discount","High Discount"))) -> High Discount | G42: =Table3[[#This Row],[Old Price]]-Table3[[#This Row],[Current Price]] -> 456 | J42: =IF(Table3[[#This Row],[Rating]]="","Missing",IF(Table3[[#This Row],[Rating]]<3,"Poor",IF(Table3[[#This Row],[Rating]]<=4.5,"Average","Excellent"))) -> Missing | K42: =IF(OR(Table3[[#This Row],[Rating]]<0,Table3[[#This Row],[Rating]]>5),"Check rating",IF(OR(Table3[[#This Row],[Discount]]<0,Table3[[#This Row],[Discount]]>1),"Check discount",IF(Table3[[#This Row],[Current Price]]>Table3[[#This Row],[Old Price]],"Check prices","OK"))) -> Check rating
A43: Modern Sofa Throw Pillow Cover-45x45cm-Blue&Red | B43: 238 | C43: =IF(Table3[[#This Row],[Current Price]]="","Missing",IF(Table3[[#This Row],[Current Price]]<=Price_Q1,"Low Price",IF(Table3[[#This Row],[Current Price]]<=Price_Q3,"Medium Price","High Price"))) -> Low Price | D43: 476 | E43: 0.5 | F43: =IF(Table3[[#This Row],[Discount]]="","Missing",IF(Table3[[#This Row],[Discount]]<0.2,"Low Discount",IF(Table3[[#This Row],[Discount]]<=0.4,"Medium Discount","High Discount"))) -> High Discount | G43: =Table3[[#This Row],[Old Price]]-Table3[[#This Row],[Current Price]] -> 238 | J43: =IF(Table3[[#This Row],[Rating]]="","Missing",IF(Table3[[#This Row],[Rating]]<3,"Poor",IF(Table3[[#This Row],[Rating]]<=4.5,"Average","Excellent"))) -> Missing | K43: =IF(OR(Table3[[#This Row],[Rating]]<0,Table3[[#This Row],[Rating]]>5),"Check rating",IF(OR(Table3[[#This Row],[Discount]]<0,Table3[[#This Row],[Discount]]>1),"Check discount",IF(Table3[[#This Row],[Current Price]]>Table3[[#This Row],[Old Price]],"Check prices","OK"))) -> Check rating
A44: Balloon Insert, Birthday Party Balloon Set, PU Leather | B44: 610 | C44: =IF(Table3[[#This Row],[Current Price]]="","Missing",IF(Table3[[#This Row],[Current Price]]<=Price_Q1,"Low Price",IF(Table3[[#This Row],[Current Price]]<=Price_Q3,"Medium Price","High Price"))) -> Medium Price | D44: 1060 | E44: 0.42 | F44: =IF(Table3[[#This Row],[Discount]]="","Missing",IF(Table3[[#This Row],[Discount]]<0.2,"Low Discount",IF(Table3[[#This Row],[Discount]]<=0.4,"Medium Discount","High Discount"))) -> High Discount | G44: =Table3[[#This Row],[Old Price]]-Table3[[#This Row],[Current Price]] -> 450 | J44: =IF(Table3[[#This Row],[Rating]]="","Missing",IF(Table3[[#This Row],[Rating]]<3,"Poor",IF(Table3[[#This Row],[Rating]]<=4.5,"Average","Excellent"))) -> Missing | K44: =IF(OR(Table3[[#This Row],[Rating]]<0,Table3[[#This Row],[Rating]]>5),"Check rating",IF(OR(Table3[[#This Row],[Discount]]<0,Table3[[#This Row],[Discount]]>1),"Check discount",IF(Table3[[#This Row],[Current Price]]>Table3[[#This Row],[Old Price]],"Check prices","OK"))) -> Check rating
A45: Shower Cap Wide Elastic Band Cover Reusable Bashroom Cap | B45: 2132 | C45: =IF(Table3[[#This Row],[Current Price]]="","Missing",IF(Table3[[#This Row],[Current Price]]<=Price_Q1,"Low Price",IF(Table3[[#This Row],[Current Price]]<=Price_Q3,"Medium Price","High Price"))) -> High Price | D45: 2169 | E45: 0.02 | F45: =IF(Table3[[#This Row],[Discount]]="","Missing",IF(Table3[[#This Row],[Discount]]<0.2,"Low Discount",IF(Table3[[#This Row],[Discount]]<=0.4,"Medium Discount","High Discount"))) -> Low Discount | G45: =Table3[[#This Row],[Old Price]]-Table3[[#This Row],[Current Price]] -> 37 | J45: =IF(Table3[[#This Row],[Rating]]="","Missing",IF(Table3[[#This Row],[Rating]]<3,"Poor",IF(Table3[[#This Row],[Rating]]<=4.5,"Average","Excellent"))) -> Missing | K45: =IF(OR(Table3[[#This Row],[Rating]]<0,Table3[[#This Row],[Rating]]>5),"Check rating",IF(OR(Table3[[#This Row],[Discount]]<0,Table3[[#This Row],[Discount]]>1),"Check discount",IF(Table3[[#This Row],[Current Price]]>Table3[[#This Row],[Old Price]],"Check prices","OK"))) -> Check rating
A46: Christmas Elk Fence Yard Lawn Decorations Cute For Holidays | B46: 999 | C46: =IF(Table3[[#This Row],[Current Price]]="","Missing",IF(Table3[[#This Row],[Current Price]]<=Price_Q1,"Low Price",IF(Table3[[#This Row],[Current Price]]<=Price_Q3,"Medium Price","High Price"))) -> Medium Price | D46: 2000 | E46: 0.5 | F46: =IF(Table3[[#This Row],[Discount]]="","Missing",IF(Table3[[#This Row],[Discount]]<0.2,"Low Discount",IF(Table3[[#This Row],[Discount]]<=0.4,"Medium Discount","High Discount"))) -> High Discount | G46: =Table3[[#This Row],[Old Price]]-Table3[[#This Row],[Current Price]] -> 1001 | J46: =IF(Table3[[#This Row],[Rating]]="","Missing",IF(Table3[[#This Row],[Rating]]<3,"Poor",IF(Table3[[#This Row],[Rating]]<=4.5,"Average","Excellent"))) -> Missing | K46: =IF(OR(Table3[[#This Row],[Rating]]<0,Table3[[#This Row],[Rating]]>5),"Check rating",IF(OR(Table3[[#This Row],[Discount]]<0,Table3[[#This Row],[Discount]]>1),"Check discount",IF(Table3[[#This Row],[Current Price]]>Table3[[#This Row],[Old Price]],"Check prices","OK"))) -> Check rating
A47: 60W Hot Melt Glue Sprayer - Efficient And Stable Glue Dispensing | B47: 1190 | C47: =IF(Table3[[#This Row],[Current Price]]="","Missing",IF(Table3[[#This Row],[Current Price]]<=Price_Q1,"Low Price",IF(Table3[[#This Row],[Current Price]]<=Price_Q3,"Medium Price","High Price"))) -> Medium Price | D47: 1785 | E47: 0.33 | F47: =IF(Table3[[#This Row],[Discount]]="","Missing",IF(Table3[[#This Row],[Discount]]<0.2,"Low Discount",IF(Table3[[#This Row],[Discount]]<=0.4,"Medium Discount","High Discount"))) -> Medium Discount | G47: =Table3[[#This Row],[Old Price]]-Table3[[#This Row],[Current Price]] -> 595 | J47: =IF(Table3[[#This Row],[Rating]]="","Missing",IF(Table3[[#This Row],[Rating]]<3,"Poor",IF(Table3[[#This Row],[Rating]]<=4.5,"Average","Excellent"))) -> Missing | K47: =IF(OR(Table3[[#This Row],[Rating]]<0,Table3[[#This Row],[Rating]]>5),"Check rating",IF(OR(Table3[[#This Row],[Discount]]<0,Table3[[#This Row],[Discount]]>1),"Check discount",IF(Table3[[#This Row],[Current Price]]>Table3[[#This Row],[Old Price]],"Check prices","OK"))) -> Check rating
A48: Car Phone Charging Stand | B48: 671 | C48: =IF(Table3[[#This Row],[Current Price]]="","Missing",IF(Table3[[#This Row],[Current Price]]<=Price_Q1,"Low Price",IF(Table3[[#This Row],[Current Price]]<=Price_Q3,"Medium Price","High Price"))) -> Medium Price | D48: 1316 | E48: 0.49 | F48: =IF(Table3[[#This Row],[Discount]]="","Missing",IF(Table3[[#This Row],[Discount]]<0.2,"Low Discount",IF(Table3[[#This Row],[Discount]]<=0.4,"Medium Discount","High Discount"))) -> High Discount | G48: =Table3[[#This Row],[Old Price]]-Table3[[#This Row],[Current Price]] -> 645 | J48: =IF(Table3[[#This Row],[Rating]]="","Missing",IF(Table3[[#This Row],[Rating]]<3,"Poor",IF(Table3[[#This Row],[Rating]]<=4.5,"Average","Excellent"))) -> Missing | K48: =IF(OR(Table3[[#This Row],[Rating]]<0,Table3[[#This Row],[Rating]]>5),"Check rating",IF(OR(Table3[[#This Row],[Discount]]<0,Table3[[#This Row],[Discount]]>1),"Check discount",IF(Table3[[#This Row],[Current Price]]>Table3[[#This Row],[Old Price]],"Check prices","OK"))) -> Check rating
...

Sheet Data_Dictionary
B1: Contains: field definitions, assumptions, thresholds, and a cleaning log | C1: New Sections Added
B2: Removing 3 full duplicate rows reduces total count to 112 valid products. | D2: Discount Amount: =[@[Old Price]]-[@[Current Price]]
B3: Used =TRIM() to remove leading,trailing and any double spaces in the product column content | D3: Rating Category: =IF([@Rating]="","Missing",IF([@Rating]<3,"Poor",IF([@Rating]<=4.5,"Average","Excellent")))
D4: Discount Category: =IF([@Discount]="","Missing",IF([@Discount]<0.2,"Low Discount",IF([@Discount]<=0.4,"Medium Discount","High Discount")))
B5: Current Price (Current Price): Converted the price range to midpoint using this formula ((1620+1980)/2 = KSh 1,800.00) for the price of row 40 Cell B40. | D5: Price Category =IF([@[Current Price]]="","Missing",IF([@[Current Price]]<=Price_Q1,"Low Price",IF([@[Current Price]]<=Price_Q3,"Medium Price","High Price")))
B6: Standardize the Current Prices(Column B) using the formula: =VALUE(SUBSTITUTE(SUBSTITUTE(B2,"KSh",""),",","")) | D6: Validation Check : =IF(OR([@Rating]<0,[@Rating]>5),"Check rating",IF(OR([@Discount]<0,[@Discount]>1),"Check discount",IF([@[Current Price]]>[@[Old Price]],"Check prices","OK")))
B7: Formatted Current Price cell as KSh #,##0.00)
D8: Defined Quartiles
B9: Old Price (Old Price): Converted the price range to midpoint using this formula (2200+3200)/2 = KSh 2,700.00) for the price of row 40 Cell C40. | D9: Price_Q1 | E9: 493
B10: Standardize the Old Prices(Column C) using the formula: =VALUE(SUBSTITUTE(SUBSTITUTE(C2,"KSh",""),",","")) | D10: Price_Q3 | E10: 1669.5
B11: Formatted Old Price cell as KSh #,##0.00)
B13: Discount (Discount): =VALUE(SUBSTITUTE(D2,"%",""))/100 (Format cell as 0%) | D13: Some formulas used in the analysis:
D14: Total products | E14: =ROWS(tblProducts[Product])
B15: Reviews (Review): Converted scraping artifacts to absolute values while leaving genuine nulls blank using the formula =IF(E2="","",ABS(VALUE(E2))) | D15: Average current price | E15: =AVERAGE(tblProducts[Current Price])
D16: Average old price | E16: =AVERAGE(tblProducts[Old Price])
B17: Rating (Ratingd): Extracted numeric values and left missing ratings blank using the formula =IF(F2="","",VALUE(SUBSTITUTE(F2," out of 5",""))) | D17: Average discount | E17: =AVERAGE(tblProducts[Discount])
D18: Average rating | E18: =AVERAGE(tblProducts[Rating])
B19: Table Conversion: Selected the cleaned range, pressed Ctrl + T, checked My table has headers, and name it tblProducts. | D19: Total reviews | E19: =SUM(tblProducts[Review])
D20: Most expensive price | E20: =MAX(tblProducts[Current Price])
D21: Least expensive price | E21: =MIN(tblProducts[Current Price])

Sheet Analysis
B1: Contains: | C1: descriptive statistics, correlation checks, and ranked product tables
B3: Defined Quartiles | J3: Below tables help to creater scatter plots
B4: Price_Q1 | C4: =_xlfn.QUARTILE.INC(tblProducts!B:B,1) -> 493
B5: Price_Q3 | C5: =_xlfn.QUARTILE.INC(tblProducts!B:B,3) -> 1669.5 | I5: Helper Table 1 | M5: Helper Table 2 | Q5: Helper Table 3
J6: Discount (X) vs. Reviews (Y) | M6: Rating (X) vs. Reviews (Y) | Q6: Current Price (X) vs. Rating (Y)
B7: Core KPIs | J7: {=_xlfn._xlws.FILTER(_xlfn.HSTACK(tblProducts!E:E,tblProducts!H:H), ISNUMBER(tblProducts!H:H))} -> 0.38 | K7: 2 | M7: {=_xlfn._xlws.FILTER(_xlfn.HSTACK(tblProducts!I:I, tblProducts!H:H), ISNUMBER(tblProducts!I:I))} -> 4.5 | N7: 2 | Q7: {=_xlfn._xlws.FILTER(_xlfn.HSTACK(tblProducts!B:B,tblProducts!I:I),ISNUMBER(tblProducts!I:I))} -> 950 | R7: 4.5
B8: Total Products | C8: =ROWS(Table3[Product]) -> 112 | J8: 0.47 | K8: 14 | M8: 4.1 | N8: 14 | Q8: 527 | R8: 4.1
B9: Average Current Price | C9: =AVERAGE(Table3[Current Price]) -> 1186.8929 | J9: 0.25 | K9: 24 | M9: 4.6 | N9: 24 | Q9: 2199 | R9: 4.6
B10: Average Old Price | C10: =AVERAGE(Table3[Old Price]) -> 1811.1071 | J10: 0.37 | K10: 7 | M10: 4.7 | N10: 7 | Q10: 1580 | R10: 4.7
B11: Average Discount | C11: =AVERAGE(Table3[Discount]) -> 0.36776786 | J11: 0.26 | K11: 5 | M11: 4.8 | N11: 5 | Q11: 1740 | R11: 4.8
B12: Average Rating | C12: =AVERAGE(Table3[Rating]) -> 3.8894737 | J12: 0.09 | K12: 15 | M12: 4 | N12: 15 | Q12: 2999 | R12: 4
B13: Total Reviews | C13: =SUM(Table3[Review]) -> 723 | J13: 0.24 | K13: 55 | M13: 4.6 | N13: 55 | Q13: 2319 | R13: 4.6
B14: Most expensive Price | C14: =MAX(Table3[Current Price]) -> 3750 | J14: 0.37 | K14: 2 | M14: 4 | N14: 2 | Q14: 988 | R14: 4
B15: Least expensive Price | C15: =MIN(Table3[Current Price]) -> 38 | J15: 0.55 | K15: 5 | M15: 4.8 | N15: 5 | Q15: 1274 | R15: 4.8
J16: 0.45 | K16: 5 | M16: 3.8 | N16: 5 | Q16: 1600 | R16: 3.8
J17: 0.2 | K17: 12 | M17: 4.1 | N17: 12 | Q17: 799 | R17: 4.1
B18: Relationship Analysis | J18: 0.34 | K18: 39 | M18: 4.7 | N18: 39 | Q18: 990 | R18: 4.7
B19: Discount vs. Reviews | C19: =CORREL(tblProducts!E:E,tblProducts!H:H) -> -0.13682272 | D19: this is a Weak negative relationship | J19: 0.47 | K19: 12 | M19: 4.8 | N19: 12 | Q19: 552 | R19: 4.8
B20: Rating vs. Reviews | C20: =CORREL(tblProducts!I:I,tblProducts!H:H) -> 0.057209035 | D20: this is a Negligible positive correlation | J20: 0.42 | K20: 6 | M20: 4.5 | N20: 6 | Q20: 501 | R20: 4.5
B21: Current Price vs. Rating | C21: =CORREL(tblProducts!B:B,tblProducts!I:I) -> 0.11009021 | D21: this is a Slight positive correlation | J21: 0.33 | K21: 9 | M21: 4.2 | N21: 9 | Q21: 1680 | R21: 4.2
J22: 0.51 | K22: 2 | M22: 5 | N22: 2 | Q22: 332 | R22: 5
J23: 0.46 | K23: 2 | M23: 5 | N23: 2 | Q23: 195 | R23: 5
B24: Top 5 Highest Rated(ties broken by Review Count) | J24: 0.49 | K24: 3 | M24: 5 | N24: 3 | Q24: 2025 | R24: 5
J25: 0.19 | K25: 5 | M25: 4.6 | N25: 5 | Q25: 2999 | R25: 4.6
J26: 0.49 | K26: 44 | M26: 4.6 | N26: 44 | Q26: 998 | R26: 4.6
J27: 0.53 | K27: 13 | M27: 3.3 | N27: 13 | Q27: 38 | R27: 3.3
J28: 0.35 | K28: 6 | M28: 4 | N28: 6 | Q28: 880 | R28: 4
J29: 0.23 | K29: 14 | M29: 4.4 | N29: 14 | Q29: 1650 | R29: 4.4
J30: 0.54 | K30: 7 | M30: 4.3 | N30: 7 | Q30: 2048 | R30: 4.3
J31: 0.35 | K31: 49 | M31: 4.6 | N31: 49 | Q31: 420 | R31: 4.6
J32: 0.18 | K32: 12 | M32: 3.8 | N32: 12 | Q32: 2880 | R32: 3.8
J33: 0.32 | K33: 13 | M33: 3.8 | N33: 13 | Q33: 1350 | R33: 3.8
J34: 0.3 | K34: 20 | M34: 4.1 | N34: 20 | Q34: 1758 | R34: 4.1
J35: 0.52 | K35: 9 | M35: 4.3 | N35: 9 | Q35: 185 | R35: 4.3
J36: 0.34 | K36: 12 | M36: 4.7 | N36: 12 | Q36: 980 | R36: 4.7
... J63: 0.5 | K63: 1 | M63: 2 | N63: 1 | Q63: 450 | R63: 2

Sheet Pivot_Tables
H2: Ranked product analysis
H7: Discount Mix
H9: Discount Category | I9: Count of Product
H10: High Discount | I10: 62
H11: Low Discount | I11: 18
H12: Medium Discount | I12: 32
H13: (blank)
H14: Grand Total | I14: 112
B15: Rating Mix | N15: Price vs. Rating
B17: Rating Category | C17: Count of Product | N17: Price Category | O17: Average of Rating
B18: Average | C18: 26 | N18: High Price | O18: 4.0842105
B19: Excellent | C19: 19 | N19: Low Price | O19: 3.6357143
B20: Missing | C20: 55 | N20: Medium Price | O20: 3.8833333
B21: Poor | C21: 12 | H21: Top 10 Products by Rating | N21: (blank)
B22: (blank) | N22: Grand Total | O22: 3.8894737
B23: Grand Total | C23: 112 | H23: Row Labels | I23: Average of Rating
H24: 40cm Gold DIY Acrylic Wall Sticker Clock | I24: 4.8
H25: Anti-Skid Absorbent Insulation Coaster For Home Office | I25: 5
H26: Bedroom Simple Floor Hanging Clothes Rack Single Pole Hat Rack - White | I26: 5
H27: Classic Black Cat Cotton Hemp Pillow Case For Home Car | I27: 5
H28: DIY File Folder, Office Drawer File Holder, Pen Holder, Desktop Storage Rack | I28: 5
